[2024-03-25T05:48:49.787+0000] {taskinstance.py:1979} INFO - Dependencies all met for dep_context=non-requeueable deps ti=<TaskInstance: Book-Recommendation-DAG.do_clean_to_parquet_task manual__2024-03-25T05:48:41.553419+00:00 [queued]>
[2024-03-25T05:48:49.793+0000] {taskinstance.py:1979} INFO - Dependencies all met for dep_context=requeueable deps ti=<TaskInstance: Book-Recommendation-DAG.do_clean_to_parquet_task manual__2024-03-25T05:48:41.553419+00:00 [queued]>
[2024-03-25T05:48:49.794+0000] {taskinstance.py:2193} INFO - Starting attempt 1 of 3
[2024-03-25T05:48:49.802+0000] {taskinstance.py:2217} INFO - Executing <Task(PythonOperator): do_clean_to_parquet_task> on 2024-03-25 05:48:41.553419+00:00
[2024-03-25T05:48:49.828+0000] {standard_task_runner.py:60} INFO - Started process 7300 to run task
[2024-03-25T05:48:49.832+0000] {standard_task_runner.py:87} INFO - Running: ['***', 'tasks', 'run', 'Book-Recommendation-DAG', 'do_clean_to_parquet_task', 'manual__2024-03-25T05:48:41.553419+00:00', '--job-id', '141', '--raw', '--subdir', 'DAGS_FOLDER/book-recommendation-dag.py', '--cfg-path', '/tmp/tmpzcorbru4']
[2024-03-25T05:48:49.836+0000] {standard_task_runner.py:88} INFO - Job 141: Subtask do_clean_to_parquet_task
[2024-03-25T05:48:49.876+0000] {task_command.py:423} INFO - Running <TaskInstance: Book-Recommendation-DAG.do_clean_to_parquet_task manual__2024-03-25T05:48:41.553419+00:00 [running]> on host 9654d883592e
[2024-03-25T05:48:49.934+0000] {taskinstance.py:2513} INFO - Exporting env vars: AIRFLOW_CTX_DAG_OWNER='iamraphson' AIRFLOW_CTX_DAG_ID='Book-Recommendation-DAG' AIRFLOW_CTX_TASK_ID='do_clean_to_parquet_task' AIRFLOW_CTX_EXECUTION_DATE='2024-03-25T05:48:41.553419+00:00' AIRFLOW_CTX_TRY_NUMBER='1' AIRFLOW_CTX_DAG_RUN_ID='manual__2024-03-25T05:48:41.553419+00:00'
[2024-03-25T05:48:52.068+0000] {taskinstance.py:2731} ERROR - Task failed with exception
Traceback (most recent call last):
  File "/home/airflow/.local/lib/python3.8/site-packages/pandas/core/indexes/range.py", line 345, in get_loc
    return self._range.index(new_key)
ValueError: 3 is not in range

The above exception was the direct cause of the following exception:

Traceback (most recent call last):
  File "/home/airflow/.local/lib/python3.8/site-packages/airflow/models/taskinstance.py", line 444, in _execute_task
    result = _execute_callable(context=context, **execute_callable_kwargs)
  File "/home/airflow/.local/lib/python3.8/site-packages/airflow/models/taskinstance.py", line 414, in _execute_callable
    return execute_callable(context=context, **execute_callable_kwargs)
  File "/home/airflow/.local/lib/python3.8/site-packages/airflow/operators/python.py", line 200, in execute
    return_value = self.execute_callable()
  File "/home/airflow/.local/lib/python3.8/site-packages/airflow/operators/python.py", line 217, in execute_callable
    return self.python_callable(*self.op_args, **self.op_kwargs)
  File "/opt/airflow/dags/book-recommendation-dag.py", line 62, in do_clean_to_parquet
    print('3', fdf[fdf[3].notnull()].head())
  File "/home/airflow/.local/lib/python3.8/site-packages/pandas/core/frame.py", line 3761, in __getitem__
    indexer = self.columns.get_loc(key)
  File "/home/airflow/.local/lib/python3.8/site-packages/pandas/core/indexes/range.py", line 347, in get_loc
    raise KeyError(key) from err
KeyError: 3
[2024-03-25T05:48:52.082+0000] {taskinstance.py:1149} INFO - Marking task as UP_FOR_RETRY. dag_id=Book-Recommendation-DAG, task_id=do_clean_to_parquet_task, execution_date=20240325T054841, start_date=20240325T054849, end_date=20240325T054852
[2024-03-25T05:48:52.091+0000] {standard_task_runner.py:107} ERROR - Failed to execute job 141 for task do_clean_to_parquet_task (3; 7300)
[2024-03-25T05:48:52.120+0000] {local_task_job_runner.py:234} INFO - Task exited with return code 1
[2024-03-25T05:48:52.178+0000] {taskinstance.py:3312} INFO - 0 downstream tasks scheduled from follow-on schedule check
