[2024-03-25T01:09:04.539+0000] {taskinstance.py:1979} INFO - Dependencies all met for dep_context=non-requeueable deps ti=<TaskInstance: Book-Recommendation-DAG.do_clean_to_parquet_task manual__2024-03-25T01:07:53.231841+00:00 [queued]>
[2024-03-25T01:09:04.546+0000] {taskinstance.py:1979} INFO - Dependencies all met for dep_context=requeueable deps ti=<TaskInstance: Book-Recommendation-DAG.do_clean_to_parquet_task manual__2024-03-25T01:07:53.231841+00:00 [queued]>
[2024-03-25T01:09:04.547+0000] {taskinstance.py:2193} INFO - Starting attempt 2 of 3
[2024-03-25T01:09:04.557+0000] {taskinstance.py:2217} INFO - Executing <Task(PythonOperator): do_clean_to_parquet_task> on 2024-03-25 01:07:53.231841+00:00
[2024-03-25T01:09:04.565+0000] {standard_task_runner.py:60} INFO - Started process 3128 to run task
[2024-03-25T01:09:04.569+0000] {standard_task_runner.py:87} INFO - Running: ['***', 'tasks', 'run', 'Book-Recommendation-DAG', 'do_clean_to_parquet_task', 'manual__2024-03-25T01:07:53.231841+00:00', '--job-id', '53', '--raw', '--subdir', 'DAGS_FOLDER/book-recommendation-dag.py', '--cfg-path', '/tmp/tmpar2v8ugu']
[2024-03-25T01:09:04.575+0000] {standard_task_runner.py:88} INFO - Job 53: Subtask do_clean_to_parquet_task
[2024-03-25T01:09:04.665+0000] {task_command.py:423} INFO - Running <TaskInstance: Book-Recommendation-DAG.do_clean_to_parquet_task manual__2024-03-25T01:07:53.231841+00:00 [running]> on host 9654d883592e
[2024-03-25T01:09:04.804+0000] {taskinstance.py:2513} INFO - Exporting env vars: AIRFLOW_CTX_DAG_OWNER='iamraphson' AIRFLOW_CTX_DAG_ID='Book-Recommendation-DAG' AIRFLOW_CTX_TASK_ID='do_clean_to_parquet_task' AIRFLOW_CTX_EXECUTION_DATE='2024-03-25T01:07:53.231841+00:00' AIRFLOW_CTX_TRY_NUMBER='2' AIRFLOW_CTX_DAG_RUN_ID='manual__2024-03-25T01:07:53.231841+00:00'
[2024-03-25T01:09:06.479+0000] {taskinstance.py:2731} ERROR - Task failed with exception
Traceback (most recent call last):
  File "pandas/_libs/lib.pyx", line 2280, in pandas._libs.lib.maybe_convert_numeric
ValueError: Unable to parse string "DK Publishing Inc"

During handling of the above exception, another exception occurred:

Traceback (most recent call last):
  File "/home/airflow/.local/lib/python3.8/site-packages/airflow/models/taskinstance.py", line 444, in _execute_task
    result = _execute_callable(context=context, **execute_callable_kwargs)
  File "/home/airflow/.local/lib/python3.8/site-packages/airflow/models/taskinstance.py", line 414, in _execute_callable
    return execute_callable(context=context, **execute_callable_kwargs)
  File "/home/airflow/.local/lib/python3.8/site-packages/airflow/operators/python.py", line 200, in execute
    return_value = self.execute_callable()
  File "/home/airflow/.local/lib/python3.8/site-packages/airflow/operators/python.py", line 217, in execute_callable
    return self.python_callable(*self.op_args, **self.op_kwargs)
  File "/opt/airflow/dags/book-recommendation-dag.py", line 27, in do_clean_to_parquet
    dataset_df = pd.read_csv(f'{dataset_download_path}{filename}', dtype=books_dtype)
  File "/home/airflow/.local/lib/python3.8/site-packages/pandas/io/parsers/readers.py", line 912, in read_csv
    return _read(filepath_or_buffer, kwds)
  File "/home/airflow/.local/lib/python3.8/site-packages/pandas/io/parsers/readers.py", line 583, in _read
    return parser.read(nrows)
  File "/home/airflow/.local/lib/python3.8/site-packages/pandas/io/parsers/readers.py", line 1704, in read
    ) = self._engine.read(  # type: ignore[attr-defined]
  File "/home/airflow/.local/lib/python3.8/site-packages/pandas/io/parsers/c_parser_wrapper.py", line 234, in read
    chunks = self._reader.read_low_memory(nrows)
  File "pandas/_libs/parsers.pyx", line 814, in pandas._libs.parsers.TextReader.read_low_memory
  File "pandas/_libs/parsers.pyx", line 891, in pandas._libs.parsers.TextReader._read_rows
  File "pandas/_libs/parsers.pyx", line 1036, in pandas._libs.parsers.TextReader._convert_column_data
  File "pandas/_libs/parsers.pyx", line 1075, in pandas._libs.parsers.TextReader._convert_tokens
  File "pandas/_libs/parsers.pyx", line 1181, in pandas._libs.parsers.TextReader._convert_with_dtype
  File "/home/airflow/.local/lib/python3.8/site-packages/pandas/core/arrays/numeric.py", line 288, in _from_sequence_of_strings
    scalars = to_numeric(strings, errors="raise", dtype_backend="numpy_nullable")
  File "/home/airflow/.local/lib/python3.8/site-packages/pandas/core/tools/numeric.py", line 217, in to_numeric
    values, new_mask = lib.maybe_convert_numeric(  # type: ignore[call-overload]  # noqa
  File "pandas/_libs/lib.pyx", line 2322, in pandas._libs.lib.maybe_convert_numeric
ValueError: Unable to parse string "DK Publishing Inc" at position 12930
[2024-03-25T01:09:06.490+0000] {taskinstance.py:1149} INFO - Marking task as UP_FOR_RETRY. dag_id=Book-Recommendation-DAG, task_id=do_clean_to_parquet_task, execution_date=20240325T010753, start_date=20240325T010904, end_date=20240325T010906
[2024-03-25T01:09:06.500+0000] {standard_task_runner.py:107} ERROR - Failed to execute job 53 for task do_clean_to_parquet_task (Unable to parse string "DK Publishing Inc" at position 12930; 3128)
[2024-03-25T01:09:06.511+0000] {local_task_job_runner.py:234} INFO - Task exited with return code 1
[2024-03-25T01:09:06.542+0000] {taskinstance.py:3312} INFO - 0 downstream tasks scheduled from follow-on schedule check
